Traceback (most recent call last):
  File "/usr/local/lib/python3.9/dist-packages/jupyter_cache/executors/utils.py", line 58, in single_nb_execution
    executenb(
  File "/usr/local/lib/python3.9/dist-packages/nbclient/client.py", line 1204, in execute
    return NotebookClient(nb=nb, resources=resources, km=km, **kwargs).execute()
  File "/usr/local/lib/python3.9/dist-packages/nbclient/util.py", line 84, in wrapped
    return just_run(coro(*args, **kwargs))
  File "/usr/local/lib/python3.9/dist-packages/nbclient/util.py", line 62, in just_run
    return loop.run_until_complete(coro)
  File "/usr/lib/python3.9/asyncio/base_events.py", line 647, in run_until_complete
    return future.result()
  File "/usr/local/lib/python3.9/dist-packages/nbclient/client.py", line 663, in async_execute
    await self.async_execute_cell(
  File "/usr/local/lib/python3.9/dist-packages/nbclient/client.py", line 965, in async_execute_cell
    await self._check_raise_for_error(cell, cell_index, exec_reply)
  File "/usr/local/lib/python3.9/dist-packages/nbclient/client.py", line 862, in _check_raise_for_error
    raise CellExecutionError.from_cell_and_msg(cell, exec_reply_content)
nbclient.exceptions.CellExecutionError: An error occurred while executing the following cell:
------------------
# reading a file and 
# printing the size of the file
document = readDoc()
print('The length of the file is:', end=' ')
print(len(document))
------------------

[0;31m[0m
[0;31mFileNotFoundError[0mTraceback (most recent call last)
[0;32m<ipython-input-10-3d2a36d056b4>[0m in [0;36m<cell line: 3>[0;34m()[0m
[1;32m      1[0m [0;31m# reading a file and[0m[0;34m[0m[0;34m[0m[0m
[1;32m      2[0m [0;31m# printing the size of the file[0m[0;34m[0m[0;34m[0m[0m
[0;32m----> 3[0;31m [0mdocument[0m [0;34m=[0m [0mreadDoc[0m[0;34m([0m[0;34m)[0m[0;34m[0m[0;34m[0m[0m
[0m[1;32m      4[0m [0mprint[0m[0;34m([0m[0;34m'The length of the file is:'[0m[0;34m,[0m [0mend[0m[0;34m=[0m[0;34m' '[0m[0;34m)[0m[0;34m[0m[0;34m[0m[0m
[1;32m      5[0m [0mprint[0m[0;34m([0m[0mlen[0m[0;34m([0m[0mdocument[0m[0;34m)[0m[0;34m)[0m[0;34m[0m[0;34m[0m[0m

[0;32m<ipython-input-8-c993d7599c9c>[0m in [0;36mreadDoc[0;34m()[0m
[1;32m     25[0m         [0;31m# pageObj = pdfR.getPage(0)[0m[0;34m[0m[0;34m[0m[0m
[1;32m     26[0m         [0;31m# document = pageObj.extractText()[0m[0;34m[0m[0;34m[0m[0m
[0;32m---> 27[0;31m         [0mreader[0m [0;34m=[0m [0mPdfReader[0m[0;34m([0m[0mname[0m[0;34m)[0m[0;34m[0m[0;34m[0m[0m
[0m[1;32m     28[0m         [0mnumber_of_pages[0m [0;34m=[0m [0mlen[0m[0;34m([0m[0mreader[0m[0;34m.[0m[0mpages[0m[0;34m)[0m[0;34m[0m[0;34m[0m[0m
[1;32m     29[0m         [0mpage[0m [0;34m=[0m [0mreader[0m[0;34m.[0m[0mpages[0m[0;34m[[0m[0;36m1[0m[0;34m][0m[0;34m[0m[0;34m[0m[0m

[0;32m/usr/local/lib/python3.9/dist-packages/PyPDF2/_reader.py[0m in [0;36m__init__[0;34m(self, stream, strict, password)[0m
[1;32m    313[0m             )
[1;32m    314[0m         [0;32mif[0m [0misinstance[0m[0;34m([0m[0mstream[0m[0;34m,[0m [0;34m([0m[0mstr[0m[0;34m,[0m [0mPath[0m[0;34m)[0m[0;34m)[0m[0;34m:[0m[0;34m[0m[0;34m[0m[0m
[0;32m--> 315[0;31m             [0;32mwith[0m [0mopen[0m[0;34m([0m[0mstream[0m[0;34m,[0m [0;34m"rb"[0m[0;34m)[0m [0;32mas[0m [0mfh[0m[0;34m:[0m[0;34m[0m[0;34m[0m[0m
[0m[1;32m    316[0m                 [0mstream[0m [0;34m=[0m [0mBytesIO[0m[0;34m([0m[0mfh[0m[0;34m.[0m[0mread[0m[0;34m([0m[0;34m)[0m[0;34m)[0m[0;34m[0m[0;34m[0m[0m
[1;32m    317[0m         [0mself[0m[0;34m.[0m[0mread[0m[0;34m([0m[0mstream[0m[0;34m)[0m[0;34m[0m[0;34m[0m[0m

[0;31mFileNotFoundError[0m: [Errno 2] No such file or directory: '/content/drive/MyDrive/sainsdata/tugas/200411100162_UTS.pdf'
FileNotFoundError: [Errno 2] No such file or directory: '/content/drive/MyDrive/sainsdata/tugas/200411100162_UTS.pdf'

