Traceback (most recent call last):
  File "/usr/local/lib/python3.9/dist-packages/jupyter_cache/executors/utils.py", line 58, in single_nb_execution
    executenb(
  File "/usr/local/lib/python3.9/dist-packages/nbclient/client.py", line 1204, in execute
    return NotebookClient(nb=nb, resources=resources, km=km, **kwargs).execute()
  File "/usr/local/lib/python3.9/dist-packages/nbclient/util.py", line 84, in wrapped
    return just_run(coro(*args, **kwargs))
  File "/usr/local/lib/python3.9/dist-packages/nbclient/util.py", line 62, in just_run
    return loop.run_until_complete(coro)
  File "/usr/lib/python3.9/asyncio/base_events.py", line 647, in run_until_complete
    return future.result()
  File "/usr/local/lib/python3.9/dist-packages/nbclient/client.py", line 663, in async_execute
    await self.async_execute_cell(
  File "/usr/local/lib/python3.9/dist-packages/nbclient/client.py", line 965, in async_execute_cell
    await self._check_raise_for_error(cell, cell_index, exec_reply)
  File "/usr/local/lib/python3.9/dist-packages/nbclient/client.py", line 862, in _check_raise_for_error
    raise CellExecutionError.from_cell_and_msg(cell, exec_reply_content)
nbclient.exceptions.CellExecutionError: An error occurred while executing the following cell:
------------------
print("There are 20 categories: %s" % (len(df.label.unique()) == 20))
print("There are 18828 records: %s" % (len(df) == 18828))
------------------

[0;31m[0m
[0;31mAttributeError[0mTraceback (most recent call last)
[0;32m<ipython-input-13-b67640b4a206>[0m in [0;36m<cell line: 1>[0;34m()[0m
[0;32m----> 1[0;31m [0mprint[0m[0;34m([0m[0;34m"There are 20 categories: %s"[0m [0;34m%[0m [0;34m([0m[0mlen[0m[0;34m([0m[0mdf[0m[0;34m.[0m[0mlabel[0m[0;34m.[0m[0munique[0m[0;34m([0m[0;34m)[0m[0;34m)[0m [0;34m==[0m [0;36m20[0m[0;34m)[0m[0;34m)[0m[0;34m[0m[0;34m[0m[0m
[0m[1;32m      2[0m [0mprint[0m[0;34m([0m[0;34m"There are 18828 records: %s"[0m [0;34m%[0m [0;34m([0m[0mlen[0m[0;34m([0m[0mdf[0m[0;34m)[0m [0;34m==[0m [0;36m18828[0m[0;34m)[0m[0;34m)[0m[0;34m[0m[0;34m[0m[0m

[0;32m/usr/local/lib/python3.9/dist-packages/pandas/core/generic.py[0m in [0;36m__getattr__[0;34m(self, name)[0m
[1;32m   5900[0m         ):
[1;32m   5901[0m             [0;32mreturn[0m [0mself[0m[0;34m[[0m[0mname[0m[0;34m][0m[0;34m[0m[0;34m[0m[0m
[0;32m-> 5902[0;31m         [0;32mreturn[0m [0mobject[0m[0;34m.[0m[0m__getattribute__[0m[0;34m([0m[0mself[0m[0;34m,[0m [0mname[0m[0;34m)[0m[0;34m[0m[0;34m[0m[0m
[0m[1;32m   5903[0m [0;34m[0m[0m
[1;32m   5904[0m     [0;32mdef[0m [0m__setattr__[0m[0;34m([0m[0mself[0m[0;34m,[0m [0mname[0m[0;34m:[0m [0mstr[0m[0;34m,[0m [0mvalue[0m[0;34m)[0m [0;34m->[0m [0;32mNone[0m[0;34m:[0m[0;34m[0m[0;34m[0m[0m

[0;31mAttributeError[0m: 'DataFrame' object has no attribute 'label'
AttributeError: 'DataFrame' object has no attribute 'label'

